Workbook

Sheet Country_1
A1: Country_1 M&E Tracker
A2: Output Indicator ID | B2: Output Indicator Description | C2: Activity ID | D2: Activity Name | E2: Component | F2: Country of Implementation | G2: Start Date | H2: End Date | I2: Program Year | J2: Quarter of Implementation | K2: Planned Number of Participants | L2: Actual Number of Participants | M2: % Achievement | N2: Means of Verification (Primary) | O2: Use Second Verification? (Yes/No) | P2: Status | Q2: Comments / Risks / Issues
A3: OI-101 | B3: People trained in targeted skills | C3: C1A001 | D3: Training workshop 1 | E3: Training | F3: Country_1 | G3: 45292 | H3: 45382 | I3: Year 1 | J3: Y1Q1 | K3: 42 | L3: 52 | M3: =IF(OR(K3="",L3=""),"",IFERROR(L3/K3,0)) -> 1.2380952 | N3: Signed attendance sheet; pre/post test forms | O3: No | P3: Completed | Q3: Completed as scheduled.
A4: OI-102 | B4: Community outreach events delivered | C4: C1A002 | D4: Community outreach campaign 2 | E4: Outreach | F4: Country_1 | G4: 45383 | H4: 45473 | I4: Year 1 | J4: Y1Q2 | K4: 47 | L4: 53 | M4: =IF(OR(K4="",L4=""),"",IFERROR(L4/K4,0)) -> 1.1276596 | N4: Activity report; photo log | O4: Yes | P4: Completed | Q4: Completed as scheduled.
A5: OI-103 | B5: Supportive supervision visits conducted | C5: C1A003 | D5: Supportive supervision visit 3 | E5: Monitoring | F5: Country_1 | G5: 45474 | H5: 45565 | I5: Year 1 | J5: Y1Q3 | K5: 52 | L5: 54 | M5: =IF(OR(K5="",L5=""),"",IFERROR(L5/K5,0)) -> 1.0384615 | N5: Supervision checklist; visit report | O5: No | P5: Completed | Q5: Completed as scheduled.
A6: OI-104 | B6: Policy dialogues facilitated | C6: C1A004 | D6: Policy dialogue 4 | E6: Advocacy | F6: Country_1 | G6: 45566 | H6: 45657 | I6: Year 1 | J6: Y1Q4 | K6: 57 | L6: 55 | M6: =IF(OR(K6="",L6=""),"",IFERROR(L6/K6,0)) -> 0.96491228 | N6: Meeting minutes; participant list | O6: No | P6: In progress | Q6: Final attendance reconciliation pending.
A7: OI-101 | B7: People trained in targeted skills | C7: C1A005 | D7: Training workshop 5 | E7: Training | F7: Country_1 | G7: 45658 | H7: 45747 | I7: Year 2 | J7: Y2Q1 | K7: 62 | L7: 56 | M7: =IF(OR(K7="",L7=""),"",IFERROR(L7/K7,0)) -> 0.90322581 | N7: Signed attendance sheet; pre/post test forms | O7: Yes | P7: In progress | Q7: Final attendance reconciliation pending.
A8: OI-102 | B8: Community outreach events delivered | C8: C1A006 | D8: Community outreach campaign 6 | E8: Outreach | F8: Country_1 | G8: 45748 | H8: 45838 | I8: Year 2 | J8: Y2Q2 | K8: 67 | L8: 57 | M8: =IF(OR(K8="",L8=""),"",IFERROR(L8/K8,0)) -> 0.85074627 | N8: Activity report; photo log | O8: No | P8: In progress | Q8: Final attendance reconciliation pending.
F9: Country_1 | M9: =IF(OR(K9="",L9=""),"",IFERROR(L9/K9,0))
F10: Country_1 | M10: =IF(OR(K10="",L10=""),"",IFERROR(L10/K10,0))
F11: Country_1 | M11: =IF(OR(K11="",L11=""),"",IFERROR(L11/K11,0))
F12: Country_1 | M12: =IF(OR(K12="",L12=""),"",IFERROR(L12/K12,0))
F13: Country_1 | M13: =IF(OR(K13="",L13=""),"",IFERROR(L13/K13,0))
F14: Country_1 | M14: =IF(OR(K14="",L14=""),"",IFERROR(L14/K14,0))
F15: Country_1 | M15: =IF(OR(K15="",L15=""),"",IFERROR(L15/K15,0))
F16: Country_1 | M16: =IF(OR(K16="",L16=""),"",IFERROR(L16/K16,0))
F17: Country_1 | M17: =IF(OR(K17="",L17=""),"",IFERROR(L17/K17,0))
F18: Country_1 | M18: =IF(OR(K18="",L18=""),"",IFERROR(L18/K18,0))
F19: Country_1 | M19: =IF(OR(K19="",L19=""),"",IFERROR(L19/K19,0))
F20: Country_1 | M20: =IF(OR(K20="",L20=""),"",IFERROR(L20/K20,0))
... F102: Country_1 | M102: =IF(OR(K102="",L102=""),"",IFERROR(L102/K102,0))
A105: Second Verification Tracker
A106: Activity ID | B106: Output Indicator ID | C106: Second Verification Type | D106: Verification Description | E106: Verification Date | F106: Verification Status | G106: Verification File Reference / Link
A107: C1A002 | B107: OI-102 | C107: Digital Verification | D107: Digital Verification completed for C1A002 | E107: 45487 | F107: Complete | G107: Ref/Country_1/C1A002
A108: C1A005 | B108: OI-101 | C108: Phone Check | D108: Phone Check scheduled / under review for C1A005 | E108: 45761 | F108: In Review | G108: Ref/Country_1/C1A005

Sheet Country_2
A1: Country_2 M&E Tracker
A2: Output Indicator ID | B2: Output Indicator Description | C2: Activity ID | D2: Activity Name | E2: Component | F2: Country of Implementation | G2: Start Date | H2: End Date | I2: Program Year | J2: Quarter of Implementation | K2: Planned Number of Participants | L2: Actual Number of Participants | M2: % Achievement | N2: Means of Verification (Primary) | O2: Use Second Verification? (Yes/No) | P2: Status | Q2: Comments / Risks / Issues
A3: OI-102 | B3: Community outreach events delivered | C3: C2A001 | D3: Community outreach campaign 1 | E3: Outreach | F3: Country_2 | G3: 45839 | H3: 45930 | I3: Year 2 | J3: Y2Q3 | K3: 49 | L3: 41 | M3: =IF(OR(K3="",L3=""),"",IFERROR(L3/K3,0)) -> 0.83673469 | N3: Activity report; photo log | O3: Yes | P3: In progress | Q3: Final attendance reconciliation pending.
A4: OI-103 | B4: Supportive supervision visits conducted | C4: C2A002 | D4: Supportive supervision visit 2 | E4: Monitoring | F4: Country_2 | G4: 45931 | H4: 46022 | I4: Year 2 | J4: Y2Q4 | K4: 54 | L4: 63 | M4: =IF(OR(K4="",L4=""),"",IFERROR(L4/K4,0)) -> 1.1666667 | N4: Supervision checklist; visit report | O4: No | P4: Completed | Q4: Completed as scheduled.
A5: OI-104 | B5: Policy dialogues facilitated | C5: C2A003 | D5: Policy dialogue 3 | E5: Advocacy | F5: Country_2 | G5: 46023 | H5: 46112 | I5: Year 3 | J5: Y3Q1 | K5: 59 | L5: 64 | M5: =IF(OR(K5="",L5=""),"",IFERROR(L5/K5,0)) -> 1.0847458 | N5: Meeting minutes; participant list | O5: No | P5: Completed | Q5: Completed as scheduled.
A6: OI-101 | B6: People trained in targeted skills | C6: C2A004 | D6: Training workshop 4 | E6: Training | F6: Country_2 | G6: 46113 | H6: 46203 | I6: Year 3 | J6: Y3Q2 | K6: 64 | L6: 65 | M6: =IF(OR(K6="",L6=""),"",IFERROR(L6/K6,0)) -> 1.015625 | N6: Signed attendance sheet; pre/post test forms | O6: Yes | P6: Completed | Q6: Completed as scheduled.
A7: OI-102 | B7: Community outreach events delivered | C7: C2A005 | D7: Community outreach campaign 5 | E7: Outreach | F7: Country_2 | G7: 46204 | H7: 46295 | I7: Year 3 | J7: Y3Q3 | K7: 69 | L7: 0 | M7: =IF(OR(K7="",L7=""),"",IFERROR(L7/K7,0)) -> 0 | N7: Activity report; photo log | O7: No | P7: Not started | Q7: Planned for a future quarter.
A8: OI-103 | B8: Supportive supervision visits conducted | C8: C2A006 | D8: Supportive supervision visit 6 | E8: Monitoring | F8: Country_2 | G8: 46296 | H8: 46387 | I8: Year 3 | J8: Y3Q4 | K8: 74 | L8: 0 | M8: =IF(OR(K8="",L8=""),"",IFERROR(L8/K8,0)) -> 0 | N8: Supervision checklist; visit report | O8: No | P8: Not started | Q8: Planned for a future quarter.
F9: Country_2 | M9: =IF(OR(K9="",L9=""),"",IFERROR(L9/K9,0))
F10: Country_2 | M10: =IF(OR(K10="",L10=""),"",IFERROR(L10/K10,0))
F11: Country_2 | M11: =IF(OR(K11="",L11=""),"",IFERROR(L11/K11,0))
F12: Country_2 | M12: =IF(OR(K12="",L12=""),"",IFERROR(L12/K12,0))
F13: Country_2 | M13: =IF(OR(K13="",L13=""),"",IFERROR(L13/K13,0))
F14: Country_2 | M14: =IF(OR(K14="",L14=""),"",IFERROR(L14/K14,0))
F15: Country_2 | M15: =IF(OR(K15="",L15=""),"",IFERROR(L15/K15,0))
F16: Country_2 | M16: =IF(OR(K16="",L16=""),"",IFERROR(L16/K16,0))
F17: Country_2 | M17: =IF(OR(K17="",L17=""),"",IFERROR(L17/K17,0))
F18: Country_2 | M18: =IF(OR(K18="",L18=""),"",IFERROR(L18/K18,0))
F19: Country_2 | M19: =IF(OR(K19="",L19=""),"",IFERROR(L19/K19,0))
F20: Country_2 | M20: =IF(OR(K20="",L20=""),"",IFERROR(L20/K20,0))
... F102: Country_2 | M102: =IF(OR(K102="",L102=""),"",IFERROR(L102/K102,0))
A105: Second Verification Tracker
A106: Activity ID | B106: Output Indicator ID | C106: Second Verification Type | D106: Verification Description | E106: Verification Date | F106: Verification Status | G106: Verification File Reference / Link
A107: C2A001 | B107: OI-102 | C107: Digital Verification | D107: Digital Verification scheduled / under review for C2A001 | E107: 45944 | F107: In Review | G107: Ref/Country_2/C2A001
A108: C2A004 | B108: OI-101 | C108: Phone Check | D108: Phone Check completed for C2A004 | E108: 46217 | F108: Complete | G108: Ref/Country_2/C2A004

Sheet Country_3
A1: Country_3 M&E Tracker
A2: Output Indicator ID | B2: Output Indicator Description | C2: Activity ID | D2: Activity Name | E2: Component | F2: Country of Implementation | G2: Start Date | H2: End Date | I2: Program Year | J2: Quarter of Implementation | K2: Planned Number of Participants | L2: Actual Number of Participants | M2: % Achievement | N2: Means of Verification (Primary) | O2: Use Second Verification? (Yes/No) | P2: Status | Q2: Comments / Risks / Issues
A3: OI-103 | B3: Supportive supervision visits conducted | C3: C3A001 | D3: Supportive supervision visit 1 | E3: Monitoring | F3: Country_3 | G3: 45292 | H3: 45382 | I3: Year 1 | J3: Y1Q1 | K3: 56 | L3: 51 | M3: =IF(OR(K3="",L3=""),"",IFERROR(L3/K3,0)) -> 0.91071429 | N3: Supervision checklist; visit report | O3: No | P3: In progress | Q3: Final attendance reconciliation pending.
A4: OI-104 | B4: Policy dialogues facilitated | C4: C3A002 | D4: Policy dialogue 2 | E4: Advocacy | F4: Country_3 | G4: 45383 | H4: 45473 | I4: Year 1 | J4: Y1Q2 | K4: 61 | L4: 52 | M4: =IF(OR(K4="",L4=""),"",IFERROR(L4/K4,0)) -> 0.85245902 | N4: Meeting minutes; participant list | O4: No | P4: In progress | Q4: Final attendance reconciliation pending.
A5: OI-101 | B5: People trained in targeted skills | C5: C3A003 | D5: Training workshop 3 | E5: Training | F5: Country_3 | G5: 45474 | H5: 45565 | I5: Year 1 | J5: Y1Q3 | K5: 66 | L5: 74 | M5: =IF(OR(K5="",L5=""),"",IFERROR(L5/K5,0)) -> 1.1212121 | N5: Signed attendance sheet; pre/post test forms | O5: Yes | P5: Completed | Q5: Completed as scheduled.
A6: OI-102 | B6: Community outreach events delivered | C6: C3A004 | D6: Community outreach campaign 4 | E6: Outreach | F6: Country_3 | G6: 45566 | H6: 45657 | I6: Year 1 | J6: Y1Q4 | K6: 71 | L6: 75 | M6: =IF(OR(K6="",L6=""),"",IFERROR(L6/K6,0)) -> 1.056338 | N6: Activity report; photo log | O6: No | P6: Completed | Q6: Completed as scheduled.
A7: OI-103 | B7: Supportive supervision visits conducted | C7: C3A005 | D7: Supportive supervision visit 5 | E7: Monitoring | F7: Country_3 | G7: 45658 | H7: 45747 | I7: Year 2 | J7: Y2Q1 | K7: 76 | L7: 76 | M7: =IF(OR(K7="",L7=""),"",IFERROR(L7/K7,0)) -> 1 | N7: Supervision checklist; visit report | O7: No | P7: Completed | Q7: Completed as scheduled.
A8: OI-104 | B8: Policy dialogues facilitated | C8: C3A006 | D8: Policy dialogue 6 | E8: Advocacy | F8: Country_3 | G8: 45748 | H8: 45838 | I8: Year 2 | J8: Y2Q2 | K8: 31 | L8: 27 | M8: =IF(OR(K8="",L8=""),"",IFERROR(L8/K8,0)) -> 0.87096774 | N8: Meeting minutes; participant list | O8: Yes | P8: In progress | Q8: Final attendance reconciliation pending.
F9: Country_3 | M9: =IF(OR(K9="",L9=""),"",IFERROR(L9/K9,0))
F10: Country_3 | M10: =IF(OR(K10="",L10=""),"",IFERROR(L10/K10,0))
F11: Country_3 | M11: =IF(OR(K11="",L11=""),"",IFERROR(L11/K11,0))
F12: Country_3 | M12: =IF(OR(K12="",L12=""),"",IFERROR(L12/K12,0))
F13: Country_3 | M13: =IF(OR(K13="",L13=""),"",IFERROR(L13/K13,0))
F14: Country_3 | M14: =IF(OR(K14="",L14=""),"",IFERROR(L14/K14,0))
F15: Country_3 | M15: =IF(OR(K15="",L15=""),"",IFERROR(L15/K15,0))
F16: Country_3 | M16: =IF(OR(K16="",L16=""),"",IFERROR(L16/K16,0))
F17: Country_3 | M17: =IF(OR(K17="",L17=""),"",IFERROR(L17/K17,0))
F18: Country_3 | M18: =IF(OR(K18="",L18=""),"",IFERROR(L18/K18,0))
F19: Country_3 | M19: =IF(OR(K19="",L19=""),"",IFERROR(L19/K19,0))
F20: Country_3 | M20: =IF(OR(K20="",L20=""),"",IFERROR(L20/K20,0))
... F102: Country_3 | M102: =IF(OR(K102="",L102=""),"",IFERROR(L102/K102,0))
A105: Second Verification Tracker
A106: Activity ID | B106: Output Indicator ID | C106: Second Verification Type | D106: Verification Description | E106: Verification Date | F106: Verification Status | G106: Verification File Reference / Link
A107: C3A003 | B107: OI-101 | C107: Phone Check | D107: Phone Check completed for C3A003 | E107: 45579 | F107: Complete | G107: Ref/Country_3/C3A003
A108: C3A006 | B108: OI-104 | C108: Site Visit | D108: Site Visit scheduled / under review for C3A006 | E108: 45852 | F108: In Review | G108: Ref/Country_3/C3A006

Sheet Country_4
A1: Country_4 M&E Tracker
A2: Output Indicator ID | B2: Output Indicator Description | C2: Activity ID | D2: Activity Name | E2: Component | F2: Country of Implementation | G2: Start Date | H2: End Date | I2: Program Year | J2: Quarter of Implementation | K2: Planned Number of Participants | L2: Actual Number of Participants | M2: % Achievement | N2: Means of Verification (Primary) | O2: Use Second Verification? (Yes/No) | P2: Status | Q2: Comments / Risks / Issues
A3: OI-104 | B3: Policy dialogues facilitated | C3: C4A001 | D3: Policy dialogue 1 | E3: Advocacy | F3: Country_4 | G3: 45839 | H3: 45930 | I3: Year 2 | J3: Y2Q3 | K3: 63 | L3: 61 | M3: =IF(OR(K3="",L3=""),"",IFERROR(L3/K3,0)) -> 0.96825397 | N3: Meeting minutes; participant list | O3: No | P3: In progress | Q3: Final attendance reconciliation pending.
A4: OI-101 | B4: People trained in targeted skills | C4: C4A002 | D4: Training workshop 2 | E4: Training | F4: Country_4 | G4: 45931 | H4: 46022 | I4: Year 2 | J4: Y2Q4 | K4: 68 | L4: 62 | M4: =IF(OR(K4="",L4=""),"",IFERROR(L4/K4,0)) -> 0.91176471 | N4: Signed attendance sheet; pre/post test forms | O4: Yes | P4: In progress | Q4: Final attendance reconciliation pending.
A5: OI-102 | B5: Community outreach events delivered | C5: C4A003 | D5: Community outreach campaign 3 | E5: Outreach | F5: Country_4 | G5: 46023 | H5: 46112 | I5: Year 3 | J5: Y3Q1 | K5: 73 | L5: 63 | M5: =IF(OR(K5="",L5=""),"",IFERROR(L5/K5,0)) -> 0.8630137 | N5: Activity report; photo log | O5: No | P5: In progress | Q5: Final attendance reconciliation pending.
A6: OI-103 | B6: Supportive supervision visits conducted | C6: C4A004 | D6: Supportive supervision visit 4 | E6: Monitoring | F6: Country_4 | G6: 46113 | H6: 46203 | I6: Year 3 | J6: Y3Q2 | K6: 78 | L6: 85 | M6: =IF(OR(K6="",L6=""),"",IFERROR(L6/K6,0)) -> 1.0897436 | N6: Supervision checklist; visit report | O6: No | P6: Completed | Q6: Completed as scheduled.
A7: OI-104 | B7: Policy dialogues facilitated | C7: C4A005 | D7: Policy dialogue 5 | E7: Advocacy | F7: Country_4 | G7: 46204 | H7: 46295 | I7: Year 3 | J7: Y3Q3 | K7: 33 | L7: 0 | M7: =IF(OR(K7="",L7=""),"",IFERROR(L7/K7,0)) -> 0 | N7: Meeting minutes; participant list | O7: Yes | P7: Not started | Q7: Planned for a future quarter.
A8: OI-101 | B8: People trained in targeted skills | C8: C4A006 | D8: Training workshop 6 | E8: Training | F8: Country_4 | G8: 46296 | H8: 46387 | I8: Year 3 | J8: Y3Q4 | K8: 38 | L8: 0 | M8: =IF(OR(K8="",L8=""),"",IFERROR(L8/K8,0)) -> 0 | N8: Signed attendance sheet; pre/post test forms | O8: No | P8: Not started | Q8: Planned for a future quarter.
F9: Country_4 | M9: =IF(OR(K9="",L9=""),"",IFERROR(L9/K9,0))
F10: Country_4 | M10: =IF(OR(K10="",L10=""),"",IFERROR(L10/K10,0))
F11: Country_4 | M11: =IF(OR(K11="",L11=""),"",IFERROR(L11/K11,0))
F12: Country_4 | M12: =IF(OR(K12="",L12=""),"",IFERROR(L12/K12,0))
F13: Country_4 | M13: =IF(OR(K13="",L13=""),"",IFERROR(L13/K13,0))
F14: Country_4 | M14: =IF(OR(K14="",L14=""),"",IFERROR(L14/K14,0))
F15: Country_4 | M15: =IF(OR(K15="",L15=""),"",IFERROR(L15/K15,0))
F16: Country_4 | M16: =IF(OR(K16="",L16=""),"",IFERROR(L16/K16,0))
F17: Country_4 | M17: =IF(OR(K17="",L17=""),"",IFERROR(L17/K17,0))
F18: Country_4 | M18: =IF(OR(K18="",L18=""),"",IFERROR(L18/K18,0))
F19: Country_4 | M19: =IF(OR(K19="",L19=""),"",IFERROR(L19/K19,0))
F20: Country_4 | M20: =IF(OR(K20="",L20=""),"",IFERROR(L20/K20,0))
... F102: Country_4 | M102: =IF(OR(K102="",L102=""),"",IFERROR(L102/K102,0))
A105: Second Verification Tracker
A106: Activity ID | B106: Output Indicator ID | C106: Second Verification Type | D106: Verification Description | E106: Verification Date | F106: Verification Status | G106: Verification File Reference / Link
A107: C4A002 | B107: OI-101 | C107: Phone Check | D107: Phone Check scheduled / under review for C4A002 | E107: 46036 | F107: In Review | G107: Ref/Country_4/C4A002
A108: C4A005 | B108: OI-104 | C108: Site Visit | D108: Site Visit scheduled / under review for C4A005 | F108: Pending | G108: Ref/Country_4/C4A005

Sheet Country_5
A1: Country_5 M&E Tracker
A2: Output Indicator ID | B2: Output Indicator Description | C2: Activity ID | D2: Activity Name | E2: Component | F2: Country of Implementation | G2: Start Date | H2: End Date | I2: Program Year | J2: Quarter of Implementation | K2: Planned Number of Participants | L2: Actual Number of Participants | M2: % Achievement | N2: Means of Verification (Primary) | O2: Use Second Verification? (Yes/No) | P2: Status | Q2: Comments / Risks / Issues
A3: OI-101 | B3: People trained in targeted skills | C3: C5A001 | D3: Training workshop 1 | E3: Training | F3: Country_5 | G3: 45292 | H3: 45382 | I3: Year 1 | J3: Y1Q1 | K3: 70 | L3: 71 | M3: =IF(OR(K3="",L3=""),"",IFERROR(L3/K3,0)) -> 1.0142857 | N3: Signed attendance sheet; pre/post test forms | O3: Yes | P3: Completed | Q3: Completed as scheduled.
A4: OI-102 | B4: Community outreach events delivered | C4: C5A002 | D4: Community outreach campaign 2 | E4: Outreach | F4: Country_5 | G4: 45383 | H4: 45473 | I4: Year 1 | J4: Y1Q2 | K4: 75 | L4: 72 | M4: =IF(OR(K4="",L4=""),"",IFERROR(L4/K4,0)) -> 0.96 | N4: Activity report; photo log | O4: No | P4: In progress | Q4: Final attendance reconciliation pending.
A5: OI-103 | B5: Supportive supervision visits conducted | C5: C5A003 | D5: Supportive supervision visit 3 | E5: Monitoring | F5: Country_5 | G5: 45474 | H5: 45565 | I5: Year 1 | J5: Y1Q3 | K5: 30 | L5: 23 | M5: =IF(OR(K5="",L5=""),"",IFERROR(L5/K5,0)) -> 0.76666667 | N5: Supervision checklist; visit report | O5: No | P5: In progress | Q5: Final attendance reconciliation pending.
A6: OI-104 | B6: Policy dialogues facilitated | C6: C5A004 | D6: Policy dialogue 4 | E6: Advocacy | F6: Country_5 | G6: 45566 | H6: 45657 | I6: Year 1 | J6: Y1Q4 | K6: 35 | L6: 45 | M6: =IF(OR(K6="",L6=""),"",IFERROR(L6/K6,0)) -> 1.2857143 | N6: Meeting minutes; participant list | O6: Yes | P6: Completed | Q6: Completed as scheduled.
A7: OI-101 | B7: People trained in targeted skills | C7: C5A005 | D7: Training workshop 5 | E7: Training | F7: Country_5 | G7: 45658 | H7: 45747 | I7: Year 2 | J7: Y2Q1 | K7: 40 | L7: 46 | M7: =IF(OR(K7="",L7=""),"",IFERROR(L7/K7,0)) -> 1.15 | N7: Signed attendance sheet; pre/post test forms | O7: No | P7: Completed | Q7: Completed as scheduled.
A8: OI-102 | B8: Community outreach events delivered | C8: C5A006 | D8: Community outreach campaign 6 | E8: Outreach | F8: Country_5 | G8: 45748 | H8: 45838 | I8: Year 2 | J8: Y2Q2 | K8: 45 | L8: 47 | M8: =IF(OR(K8="",L8=""),"",IFERROR(L8/K8,0)) -> 1.0444444 | N8: Activity report; photo log | O8: No | P8: Completed | Q8: Completed as scheduled.
F9: Country_5 | M9: =IF(OR(K9="",L9=""),"",IFERROR(L9/K9,0))
F10: Country_5 | M10: =IF(OR(K10="",L10=""),"",IFERROR(L10/K10,0))
F11: Country_5 | M11: =IF(OR(K11="",L11=""),"",IFERROR(L11/K11,0))
F12: Country_5 | M12: =IF(OR(K12="",L12=""),"",IFERROR(L12/K12,0))
F13: Country_5 | M13: =IF(OR(K13="",L13=""),"",IFERROR(L13/K13,0))
F14: Country_5 | M14: =IF(OR(K14="",L14=""),"",IFERROR(L14/K14,0))
F15: Country_5 | M15: =IF(OR(K15="",L15=""),"",IFERROR(L15/K15,0))
F16: Country_5 | M16: =IF(OR(K16="",L16=""),"",IFERROR(L16/K16,0))
F17: Country_5 | M17: =IF(OR(K17="",L17=""),"",IFERROR(L17/K17,0))
F18: Country_5 | M18: =IF(OR(K18="",L18=""),"",IFERROR(L18/K18,0))
F19: Country_5 | M19: =IF(OR(K19="",L19=""),"",IFERROR(L19/K19,0))
F20: Country_5 | M20: =IF(OR(K20="",L20=""),"",IFERROR(L20/K20,0))
... F102: Country_5 | M102: =IF(OR(K102="",L102=""),"",IFERROR(L102/K102,0))
A105: Second Verification Tracker
A106: Activity ID | B106: Output Indicator ID | C106: Second Verification Type | D106: Verification Description | E106: Verification Date | F106: Verification Status | G106: Verification File Reference / Link
A107: C5A001 | B107: OI-101 | C107: Phone Check | D107: Phone Check completed for C5A001 | E107: 45396 | F107: Complete | G107: Ref/Country_5/C5A001
A108: C5A004 | B108: OI-104 | C108: Site Visit | D108: Site Visit completed for C5A004 | E108: 45671 | F108: Complete | G108: Ref/Country_5/C5A004

Sheet Country_6
A1: Country_6 M&E Tracker
A2: Output Indicator ID | B2: Output Indicator Description | C2: Activity ID | D2: Activity Name | E2: Component | F2: Country of Implementation | G2: Start Date | H2: End Date | I2: Program Year | J2: Quarter of Implementation | K2: Planned Number of Participants | L2: Actual Number of Participants | M2: % Achievement | N2: Means of Verification (Primary) | O2: Use Second Verification? (Yes/No) | P2: Status | Q2: Comments / Risks / Issues
A3: OI-102 | B3: Community outreach events delivered | C3: C6A001 | D3: Community outreach campaign 1 | E3: Outreach | F3: Country_6 | G3: 45839 | H3: 45930 | I3: Year 2 | J3: Y2Q3 | K3: 77 | L3: 81 | M3: =IF(OR(K3="",L3=""),"",IFERROR(L3/K3,0)) -> 1.0519481 | N3: Activity report; photo log | O3: No | P3: Completed | Q3: Completed as scheduled.
A4: OI-103 | B4: Supportive supervision visits conducted | C4: C6A002 | D4: Supportive supervision visit 2 | E4: Monitoring | F4: Country_6 | G4: 45931 | H4: 46022 | I4: Year 2 | J4: Y2Q4 | K4: 32 | L4: 32 | M4: =IF(OR(K4="",L4=""),"",IFERROR(L4/K4,0)) -> 1 | N4: Supervision checklist; visit report | O4: No | P4: Completed | Q4: Completed as scheduled.
A5: OI-104 | B5: Policy dialogues facilitated | C5: C6A003 | D5: Policy dialogue 3 | E5: Advocacy | F5: Country_6 | G5: 46023 | H5: 46112 | I5: Year 3 | J5: Y3Q1 | K5: 37 | L5: 33 | M5: =IF(OR(K5="",L5=""),"",IFERROR(L5/K5,0)) -> 0.89189189 | N5: Meeting minutes; participant list | O5: Yes | P5: In progress | Q5: Final attendance reconciliation pending.
A6: OI-101 | B6: People trained in targeted skills | C6: C6A004 | D6: Training workshop 4 | E6: Training | F6: Country_6 | G6: 46113 | H6: 46203 | I6: Year 3 | J6: Y3Q2 | K6: 42 | L6: 34 | M6: =IF(OR(K6="",L6=""),"",IFERROR(L6/K6,0)) -> 0.80952381 | N6: Signed attendance sheet; pre/post test forms | O6: No | P6: In progress | Q6: Final attendance reconciliation pending.
A7: OI-102 | B7: Community outreach events delivered | C7: C6A005 | D7: Community outreach campaign 5 | E7: Outreach | F7: Country_6 | G7: 46204 | H7: 46295 | I7: Year 3 | J7: Y3Q3 | K7: 47 | L7: 0 | M7: =IF(OR(K7="",L7=""),"",IFERROR(L7/K7,0)) -> 0 | N7: Activity report; photo log | O7: No | P7: Not started | Q7: Planned for a future quarter.
A8: OI-103 | B8: Supportive supervision visits conducted | C8: C6A006 | D8: Supportive supervision visit 6 | E8: Monitoring | F8: Country_6 | G8: 46296 | H8: 46387 | I8: Year 3 | J8: Y3Q4 | K8: 52 | L8: 0 | M8: =IF(OR(K8="",L8=""),"",IFERROR(L8/K8,0)) -> 0 | N8: Supervision checklist; visit report | O8: Yes | P8: Not started | Q8: Planned for a future quarter.
F9: Country_6 | M9: =IF(OR(K9="",L9=""),"",IFERROR(L9/K9,0))
F10: Country_6 | M10: =IF(OR(K10="",L10=""),"",IFERROR(L10/K10,0))
F11: Country_6 | M11: =IF(OR(K11="",L11=""),"",IFERROR(L11/K11,0))
F12: Country_6 | M12: =IF(OR(K12="",L12=""),"",IFERROR(L12/K12,0))
F13: Country_6 | M13: =IF(OR(K13="",L13=""),"",IFERROR(L13/K13,0))
F14: Country_6 | M14: =IF(OR(K14="",L14=""),"",IFERROR(L14/K14,0))
F15: Country_6 | M15: =IF(OR(K15="",L15=""),"",IFERROR(L15/K15,0))
F16: Country_6 | M16: =IF(OR(K16="",L16=""),"",IFERROR(L16/K16,0))
F17: Country_6 | M17: =IF(OR(K17="",L17=""),"",IFERROR(L17/K17,0))
F18: Country_6 | M18: =IF(OR(K18="",L18=""),"",IFERROR(L18/K18,0))
F19: Country_6 | M19: =IF(OR(K19="",L19=""),"",IFERROR(L19/K19,0))
F20: Country_6 | M20: =IF(OR(K20="",L20=""),"",IFERROR(L20/K20,0))
... F102: Country_6 | M102: =IF(OR(K102="",L102=""),"",IFERROR(L102/K102,0))
A105: Second Verification Tracker
A106: Activity ID | B106: Output Indicator ID | C106: Second Verification Type | D106: Verification Description | E106: Verification Date | F106: Verification Status | G106: Verification File Reference / Link
A107: C6A003 | B107: OI-104 | C107: Site Visit | D107: Site Visit scheduled / under review for C6A003 | E107: 46126 | F107: In Review | G107: Ref/Country_6/C6A003
A108: C6A006 | B108: OI-103 | C108: Document Review | D108: Document Review scheduled / under review for C6A006 | F108: Pending | G108: Ref/Country_6/C6A006

Sheet Country_7
A1: Country_7 M&E Tracker
A2: Output Indicator ID | B2: Output Indicator Description | C2: Activity ID | D2: Activity Name | E2: Component | F2: Country of Implementation | G2: Start Date | H2: End Date | I2: Program Year | J2: Quarter of Implementation | K2: Planned Number of Participants | L2: Actual Number of Participants | M2: % Achievement | N2: Means of Verification (Primary) | O2: Use Second Verification? (Yes/No) | P2: Status | Q2: Comments / Risks / Issues
A3: OI-103 | B3: Supportive supervision visits conducted | C3: C7A001 | D3: Supportive supervision visit 1 | E3: Monitoring | F3: Country_7 | G3: 45292 | H3: 45382 | I3: Year 1 | J3: Y1Q1 | K3: 34 | L3: 41 | M3: =IF(OR(K3="",L3=""),"",IFERROR(L3/K3,0)) -> 1.2058824 | N3: Supervision checklist; visit report | O3: No | P3: Completed | Q3: Completed as scheduled.
A4: OI-104 | B4: Policy dialogues facilitated | C4: C7A002 | D4: Policy dialogue 2 | E4: Advocacy | F4: Country_7 | G4: 45383 | H4: 45473 | I4: Year 1 | J4: Y1Q2 | K4: 39 | L4: 42 | M4: =IF(OR(K4="",L4=""),"",IFERROR(L4/K4,0)) -> 1.0769231 | N4: Meeting minutes; participant list | O4: Yes | P4: Completed | Q4: Completed as scheduled.
A5: OI-101 | B5: People trained in targeted skills | C5: C7A003 | D5: Training workshop 3 | E5: Training | F5: Country_7 | G5: 45474 | H5: 45565 | I5: Year 1 | J5: Y1Q3 | K5: 44 | L5: 43 | M5: =IF(OR(K5="",L5=""),"",IFERROR(L5/K5,0)) -> 0.97727273 | N5: Signed attendance sheet; pre/post test forms | O5: No | P5: In progress | Q5: Final attendance reconciliation pending.
A6: OI-102 | B6: Community outreach events delivered | C6: C7A004 | D6: Community outreach campaign 4 | E6: Outreach | F6: Country_7 | G6: 45566 | H6: 45657 | I6: Year 1 | J6: Y1Q4 | K6: 49 | L6: 44 | M6: =IF(OR(K6="",L6=""),"",IFERROR(L6/K6,0)) -> 0.89795918 | N6: Activity report; photo log | O6: No | P6: In progress | Q6: Final attendance reconciliation pending.
A7: OI-103 | B7: Supportive supervision visits conducted | C7: C7A005 | D7: Supportive supervision visit 5 | E7: Monitoring | F7: Country_7 | G7: 45658 | H7: 45747 | I7: Year 2 | J7: Y2Q1 | K7: 54 | L7: 45 | M7: =IF(OR(K7="",L7=""),"",IFERROR(L7/K7,0)) -> 0.83333333 | N7: Supervision checklist; visit report | O7: Yes | P7: In progress | Q7: Final attendance reconciliation pending.
A8: OI-104 | B8: Policy dialogues facilitated | C8: C7A006 | D8: Policy dialogue 6 | E8: Advocacy | F8: Country_7 | G8: 45748 | H8: 45838 | I8: Year 2 | J8: Y2Q2 | K8: 59 | L8: 67 | M8: =IF(OR(K8="",L8=""),"",IFERROR(L8/K8,0)) -> 1.1355932 | N8: Meeting minutes; participant list | O8: No | P8: Completed | Q8: Completed as scheduled.
F9: Country_7 | M9: =IF(OR(K9="",L9=""),"",IFERROR(L9/K9,0))
F10: Country_7 | M10: =IF(OR(K10="",L10=""),"",IFERROR(L10/K10,0))
F11: Country_7 | M11: =IF(OR(K11="",L11=""),"",IFERROR(L11/K11,0))
F12: Country_7 | M12: =IF(OR(K12="",L12=""),"",IFERROR(L12/K12,0))
F13: Country_7 | M13: =IF(OR(K13="",L13=""),"",IFERROR(L13/K13,0))
F14: Country_7 | M14: =IF(OR(K14="",L14=""),"",IFERROR(L14/K14,0))
F15: Country_7 | M15: =IF(OR(K15="",L15=""),"",IFERROR(L15/K15,0))
F16: Country_7 | M16: =IF(OR(K16="",L16=""),"",IFERROR(L16/K16,0))
F17: Country_7 | M17: =IF(OR(K17="",L17=""),"",IFERROR(L17/K17,0))
F18: Country_7 | M18: =IF(OR(K18="",L18=""),"",IFERROR(L18/K18,0))
F19: Country_7 | M19: =IF(OR(K19="",L19=""),"",IFERROR(L19/K19,0))
F20: Country_7 | M20: =IF(OR(K20="",L20=""),"",IFERROR(L20/K20,0))
... F102: Country_7 | M102: =IF(OR(K102="",L102=""),"",IFERROR(L102/K102,0))
A105: Second Verification Tracker
A106: Activity ID | B106: Output Indicator ID | C106: Second Verification Type | D106: Verification Description | E106: Verification Date | F106: Verification Status | G106: Verification File Reference / Link
A107: C7A002 | B107: OI-104 | C107: Site Visit | D107: Site Visit completed for C7A002 | E107: 45487 | F107: Complete | G107: Ref/Country_7/C7A002
A108: C7A005 | B108: OI-103 | C108: Document Review | D108: Document Review scheduled / under review for C7A005 | E108: 45761 | F108: In Review | G108: Ref/Country_7/C7A005

Sheet Country_8
A1: Country_8 M&E Tracker
A2: Output Indicator ID | B2: Output Indicator Description | C2: Activity ID | D2: Activity Name | E2: Component | F2: Country of Implementation | G2: Start Date | H2: End Date | I2: Program Year | J2: Quarter of Implementation | K2: Planned Number of Participants | L2: Actual Number of Participants | M2: % Achievement | N2: Means of Verification (Primary) | O2: Use Second Verification? (Yes/No) | P2: Status | Q2: Comments / Risks / Issues
A3: OI-104 | B3: Policy dialogues facilitated | C3: C8A001 | D3: Policy dialogue 1 | E3: Advocacy | F3: Country_8 | G3: 45839 | H3: 45930 | I3: Year 2 | J3: Y2Q3 | K3: 41 | L3: 51 | M3: =IF(OR(K3="",L3=""),"",IFERROR(L3/K3,0)) -> 1.2439024 | N3: Meeting minutes; participant list | O3: Yes | P3: Completed | Q3: Completed as scheduled.
A4: OI-101 | B4: People trained in targeted skills | C4: C8A002 | D4: Training workshop 2 | E4: Training | F4: Country_8 | G4: 45931 | H4: 46022 | I4: Year 2 | J4: Y2Q4 | K4: 46 | L4: 52 | M4: =IF(OR(K4="",L4=""),"",IFERROR(L4/K4,0)) -> 1.1304348 | N4: Signed attendance sheet; pre/post test forms | O4: No | P4: Completed | Q4: Completed as scheduled.
A5: OI-102 | B5: Community outreach events delivered | C5: C8A003 | D5: Community outreach campaign 3 | E5: Outreach | F5: Country_8 | G5: 46023 | H5: 46112 | I5: Year 3 | J5: Y3Q1 | K5: 51 | L5: 53 | M5: =IF(OR(K5="",L5=""),"",IFERROR(L5/K5,0)) -> 1.0392157 | N5: Activity report; photo log | O5: No | P5: Completed | Q5: Completed as scheduled.
A6: OI-103 | B6: Supportive supervision visits conducted | C6: C8A004 | D6: Supportive supervision visit 4 | E6: Monitoring | F6: Country_8 | G6: 46113 | H6: 46203 | I6: Year 3 | J6: Y3Q2 | K6: 56 | L6: 54 | M6: =IF(OR(K6="",L6=""),"",IFERROR(L6/K6,0)) -> 0.96428571 | N6: Supervision checklist; visit report | O6: Yes | P6: In progress | Q6: Final attendance reconciliation pending.
A7: OI-104 | B7: Policy dialogues facilitated | C7: C8A005 | D7: Policy dialogue 5 | E7: Advocacy | F7: Country_8 | G7: 46204 | H7: 46295 | I7: Year 3 | J7: Y3Q3 | K7: 61 | L7: 0 | M7: =IF(OR(K7="",L7=""),"",IFERROR(L7/K7,0)) -> 0 | N7: Meeting minutes; participant list | O7: No | P7: Not started | Q7: Planned for a future quarter.
A8: OI-101 | B8: People trained in targeted skills | C8: C8A006 | D8: Training workshop 6 | E8: Training | F8: Country_8 | G8: 46296 | H8: 46387 | I8: Year 3 | J8: Y3Q4 | K8: 66 | L8: 0 | M8: =IF(OR(K8="",L8=""),"",IFERROR(L8/K8,0)) -> 0 | N8: Signed attendance sheet; pre/post test forms | O8: No | P8: Not started | Q8: Planned for a future quarter.
F9: Country_8 | M9: =IF(OR(K9="",L9=""),"",IFERROR(L9/K9,0))
F10: Country_8 | M10: =IF(OR(K10="",L10=""),"",IFERROR(L10/K10,0))
F11: Country_8 | M11: =IF(OR(K11="",L11=""),"",IFERROR(L11/K11,0))
F12: Country_8 | M12: =IF(OR(K12="",L12=""),"",IFERROR(L12/K12,0))
F13: Country_8 | M13: =IF(OR(K13="",L13=""),"",IFERROR(L13/K13,0))
F14: Country_8 | M14: =IF(OR(K14="",L14=""),"",IFERROR(L14/K14,0))
F15: Country_8 | M15: =IF(OR(K15="",L15=""),"",IFERROR(L15/K15,0))
F16: Country_8 | M16: =IF(OR(K16="",L16=""),"",IFERROR(L16/K16,0))
F17: Country_8 | M17: =IF(OR(K17="",L17=""),"",IFERROR(L17/K17,0))
F18: Country_8 | M18: =IF(OR(K18="",L18=""),"",IFERROR(L18/K18,0))
F19: Country_8 | M19: =IF(OR(K19="",L19=""),"",IFERROR(L19/K19,0))
F20: Country_8 | M20: =IF(OR(K20="",L20=""),"",IFERROR(L20/K20,0))
... F102: Country_8 | M102: =IF(OR(K102="",L102=""),"",IFERROR(L102/K102,0))
A105: Second Verification Tracker
A106: Activity ID | B106: Output Indicator ID | C106: Second Verification Type | D106: Verification Description | E106: Verification Date | F106: Verification Status | G106: Verification File Reference / Link
A107: C8A001 | B107: OI-104 | C107: Site Visit | D107: Site Visit completed for C8A001 | E107: 45944 | F107: Complete | G107: Ref/Country_8/C8A001
A108: C8A004 | B108: OI-103 | C108: Document Review | D108: Document Review scheduled / under review for C8A004 | E108: 46217 | F108: In Review | G108: Ref/Country_8/C8A004

Sheet Dashboard
A1: Monitoring & Evaluation Dashboard
A3: Filters | E3: Total Planned Participants | H3: Total Actual Participants | K3: % Achievement | N3: Activities
A4: Country | B4: All | C4: =IF(B4="All","*",B4) -> * | E4: =SUMIFS(Consolidated_Data!$K$2:$K$801,Consolidated_Data!$C$2:$C$801,"<>",Consolidated_Data!$F$2:$F$801,$C$4,Consolidated_Data!$E$2:$E$801,$C$5,Consolidated_Data!$A$2:$A$801,$C$6,Consolidated_Data!$I$2:$I$801,$C$7,Consolidated_Data!$J$2:$J$801,$C$8) -> 2592 | H4: =SUMIFS(Consolidated_Data!$L$2:$L$801,Consolidated_Data!$C$2:$C$801,"<>",Consolidated_Data!$F$2:$F$801,$C$4,Consolidated_Data!$E$2:$E$801,$C$5,Consolidated_Data!$A$2:$A$801,$C$6,Consolidated_Data!$I$2:$I$801,$C$7,Consolidated_Data!$J$2:$J$801,$C$8) -> 2162 | K4: =IFERROR(H4/E4,0) -> 0.83410494 | N4: =SUM(E13:E16) -> 48
A5: Component | B5: All | C5: =IF(B5="All","*",B5) -> *
A6: Output Indicator ID | B6: All | C6: =IF(B6="All","*",B6) -> *
A7: Program Year | B7: All | C7: =IF(B7="All","*",B7) -> * | E7: Completed | H7: Delayed | K7: 2nd Verification Needed | N7: Tip: edit country sheets and refresh formulas by opening in Excel.
A8: Quarter | B8: All | C8: =IF(B8="All","*",B8) -> * | E8: =COUNTIFS(Consolidated_Data!$C$2:$C$801,"<>",Consolidated_Data!$P$2:$P$801,"Completed",Consolidated_Data!$F$2:$F$801,$C$4,Consolidated_Data!$E$2:$E$801,$C$5,Consolidated_Data!$A$2:$A$801,$C$6,Consolidated_Data!$I$2:$I$801,$C$7,Consolidated_Data!$J$2:$J$801,$C$8) -> 22 | H8: =COUNTIFS(Consolidated_Data!$C$2:$C$801,"<>",Consolidated_Data!$P$2:$P$801,"Delayed",Consolidated_Data!$F$2:$F$801,$C$4,Consolidated_Data!$E$2:$E$801,$C$5,Consolidated_Data!$A$2:$A$801,$C$6,Consolidated_Data!$I$2:$I$801,$C$7,Consolidated_Data!$J$2:$J$801,$C$8) -> 0 | K8: =COUNTIFS(Consolidated_Data!$C$2:$C$801,"<>",Consolidated_Data!$O$2:$O$801,"Yes",Consolidated_Data!$F$2:$F$801,$C$4,Consolidated_Data!$E$2:$E$801,$C$5,Consolidated_Data!$A$2:$A$801,$C$6,Consolidated_Data!$I$2:$I$801,$C$7,Consolidated_Data!$J$2:$J$801,$C$8) -> 16
A11: By Component | G11: Status Breakdown | J11: By Output Indicator
A12: Component | B12: Planned | C12: Actual | D12: % Ach. | E12: Activities | G12: Status | H12: Count | J12: Indicator | K12: Planned | L12: Actual | M12: % Ach. | N12: Activities
A13: Training | B13: =SUMIFS(Consolidated_Data!$K$2:$K$801,Consolidated_Data!$C$2:$C$801,"<>",Consolidated_Data!$E$2:$E$801,$A13,Consolidated_Data!$F$2:$F$801,$C$4,Consolidated_Data!$E$2:$E$801,$C$5,Consolidated_Data!$A$2:$A$801,$C$6,Consolidated_Data!$I$2:$I$801,$C$7,Consolidated_Data!$J$2:$J$801,$C$8) -> 648 | C13: =SUMIFS(Consolidated_Data!$L$2:$L$801,Consolidated_Data!$C$2:$C$801,"<>",Consolidated_Data!$E$2:$E$801,$A13,Consolidated_Data!$F$2:$F$801,$C$4,Consolidated_Data!$E$2:$E$801,$C$5,Consolidated_Data!$A$2:$A$801,$C$6,Consolidated_Data!$I$2:$I$801,$C$7,Consolidated_Data!$J$2:$J$801,$C$8) -> 555 | D13: =IFERROR(C13/B13,0) -> 0.85648148 | E13: =COUNTIFS(Consolidated_Data!$C$2:$C$801,"<>",Consolidated_Data!$E$2:$E$801,$A13,Consolidated_Data!$F$2:$F$801,$C$4,Consolidated_Data!$E$2:$E$801,$C$5,Consolidated_Data!$A$2:$A$801,$C$6,Consolidated_Data!$I$2:$I$801,$C$7,Consolidated_Data!$J$2:$J$801,$C$8) -> 12 | G13: Not started | H13: =COUNTIFS(Consolidated_Data!$C$2:$C$801,"<>",Consolidated_Data!$P$2:$P$801,$G13,Consolidated_Data!$F$2:$F$801,$C$4,Consolidated_Data!$E$2:$E$801,$C$5,Consolidated_Data!$A$2:$A$801,$C$6,Consolidated_Data!$I$2:$I$801,$C$7,Consolidated_Data!$J$2:$J$801,$C$8) -> 8 | J13: OI-101 | K13: =SUMIFS(Consolidated_Data!$K$2:$K$801,Consolidated_Data!$C$2:$C$801,"<>",Consolidated_Data!$A$2:$A$801,$J13,Consolidated_Data!$F$2:$F$801,$C$4,Consolidated_Data!$E$2:$E$801,$C$5,Consolidated_Data!$A$2:$A$801,$C$6,Consolidated_Data!$I$2:$I$801,$C$7,Consolidated_Data!$J$2:$J$801,$C$8) -> 648 | L13: =SUMIFS(Consolidated_Data!$L$2:$L$801,Consolidated_Data!$C$2:$C$801,"<>",Consolidated_Data!$A$2:$A$801,$J13,Consolidated_Data!$F$2:$F$801,$C$4,Consolidated_Data!$E$2:$E$801,$C$5,Consolidated_Data!$A$2:$A$801,$C$6,Consolidated_Data!$I$2:$I$801,$C$7,Consolidated_Data!$J$2:$J$801,$C$8) -> 555 | M13: =IFERROR(L13/K13,0) -> 0.85648148 | N13: =COUNTIFS(Consolidated_Data!$C$2:$C$801,"<>",Consolidated_Data!$A$2:$A$801,$J13,Consolidated_Data!$F$2:$F$801,$C$4,Consolidated_Data!$E$2:$E$801,$C$5,Consolidated_Data!$A$2:$A$801,$C$6,Consolidated_Data!$I$2:$I$801,$C$7,Consolidated_Data!$J$2:$J$801,$C$8) -> 12
A14: Outreach | B14: =SUMIFS(Consolidated_Data!$K$2:$K$801,Consolidated_Data!$C$2:$C$801,"<>",Consolidated_Data!$E$2:$E$801,$A14,Consolidated_Data!$F$2:$F$801,$C$4,Consolidated_Data!$E$2:$E$801,$C$5,Consolidated_Data!$A$2:$A$801,$C$6,Consolidated_Data!$I$2:$I$801,$C$7,Consolidated_Data!$J$2:$J$801,$C$8) -> 720 | C14: =SUMIFS(Consolidated_Data!$L$2:$L$801,Consolidated_Data!$C$2:$C$801,"<>",Consolidated_Data!$E$2:$E$801,$A14,Consolidated_Data!$F$2:$F$801,$C$4,Consolidated_Data!$E$2:$E$801,$C$5,Consolidated_Data!$A$2:$A$801,$C$6,Consolidated_Data!$I$2:$I$801,$C$7,Consolidated_Data!$J$2:$J$801,$C$8) -> 586 | D14: =IFERROR(C14/B14,0) -> 0.81388889 | E14: =COUNTIFS(Consolidated_Data!$C$2:$C$801,"<>",Consolidated_Data!$E$2:$E$801,$A14,Consolidated_Data!$F$2:$F$801,$C$4,Consolidated_Data!$E$2:$E$801,$C$5,Consolidated_Data!$A$2:$A$801,$C$6,Consolidated_Data!$I$2:$I$801,$C$7,Consolidated_Data!$J$2:$J$801,$C$8) -> 12 | G14: In progress | H14: =COUNTIFS(Consolidated_Data!$C$2:$C$801,"<>",Consolidated_Data!$P$2:$P$801,$G14,Consolidated_Data!$F$2:$F$801,$C$4,Consolidated_Data!$E$2:$E$801,$C$5,Consolidated_Data!$A$2:$A$801,$C$6,Consolidated_Data!$I$2:$I$801,$C$7,Consolidated_Data!$J$2:$J$801,$C$8) -> 18 | J14: OI-102 | K14: =SUMIFS(Consolidated_Data!$K$2:$K$801,Consolidated_Data!$C$2:$C$801,"<>",Consolidated_Data!$A$2:$A$801,$J14,Consolidated_Data!$F$2:$F$801,$C$4,Consolidated_Data!$E$2:$E$801,$C$5,Consolidated_Data!$A$2:$A$801,$C$6,Consolidated_Data!$I$2:$I$801,$C$7,Consolidated_Data!$J$2:$J$801,$C$8) -> 720 | L14: =SUMIFS(Consolidated_Data!$L$2:$L$801,Consolidated_Data!$C$2:$C$801,"<>",Consolidated_Data!$A$2:$A$801,$J14,Consolidated_Data!$F$2:$F$801,$C$4,Consolidated_Data!$E$2:$E$801,$C$5,Consolidated_Data!$A$2:$A$801,$C$6,Consolidated_Data!$I$2:$I$801,$C$7,Consolidated_Data!$J$2:$J$801,$C$8) -> 586 | M14: =IFERROR(L14/K14,0) -> 0.81388889 | N14: =COUNTIFS(Consolidated_Data!$C$2:$C$801,"<>",Consolidated_Data!$A$2:$A$801,$J14,Consolidated_Data!$F$2:$F$801,$C$4,Consolidated_Data!$E$2:$E$801,$C$5,Consolidated_Data!$A$2:$A$801,$C$6,Consolidated_Data!$I$2:$I$801,$C$7,Consolidated_Data!$J$2:$J$801,$C$8) -> 12
A15: Monitoring | B15: =SUMIFS(Consolidated_Data!$K$2:$K$801,Consolidated_Data!$C$2:$C$801,"<>",Consolidated_Data!$E$2:$E$801,$A15,Consolidated_Data!$F$2:$F$801,$C$4,Consolidated_Data!$E$2:$E$801,$C$5,Consolidated_Data!$A$2:$A$801,$C$6,Consolidated_Data!$I$2:$I$801,$C$7,Consolidated_Data!$J$2:$J$801,$C$8) -> 648 | C15: =SUMIFS(Consolidated_Data!$L$2:$L$801,Consolidated_Data!$C$2:$C$801,"<>",Consolidated_Data!$E$2:$E$801,$A15,Consolidated_Data!$F$2:$F$801,$C$4,Consolidated_Data!$E$2:$E$801,$C$5,Consolidated_Data!$A$2:$A$801,$C$6,Consolidated_Data!$I$2:$I$801,$C$7,Consolidated_Data!$J$2:$J$801,$C$8) -> 524 | D15: =IFERROR(C15/B15,0) -> 0.80864198 | E15: =COUNTIFS(Consolidated_Data!$C$2:$C$801,"<>",Consolidated_Data!$E$2:$E$801,$A15,Consolidated_Data!$F$2:$F$801,$C$4,Consolidated_Data!$E$2:$E$801,$C$5,Consolidated_Data!$A$2:$A$801,$C$6,Consolidated_Data!$I$2:$I$801,$C$7,Consolidated_Data!$J$2:$J$801,$C$8) -> 12 | G15: Completed | H15: =COUNTIFS(Consolidated_Data!$C$2:$C$801,"<>",Consolidated_Data!$P$2:$P$801,$G15,Consolidated_Data!$F$2:$F$801,$C$4,Consolidated_Data!$E$2:$E$801,$C$5,Consolidated_Data!$A$2:$A$801,$C$6,Consolidated_Data!$I$2:$I$801,$C$7,Consolidated_Data!$J$2:$J$801,$C$8) -> 22 | J15: OI-103 | K15: =SUMIFS(Consolidated_Data!$K$2:$K$801,Consolidated_Data!$C$2:$C$801,"<>",Consolidated_Data!$A$2:$A$801,$J15,Consolidated_Data!$F$2:$F$801,$C$4,Consolidated_Data!$E$2:$E$801,$C$5,Consolidated_Data!$A$2:$A$801,$C$6,Consolidated_Data!$I$2:$I$801,$C$7,Consolidated_Data!$J$2:$J$801,$C$8) -> 648 | L15: =SUMIFS(Consolidated_Data!$L$2:$L$801,Consolidated_Data!$C$2:$C$801,"<>",Consolidated_Data!$A$2:$A$801,$J15,Consolidated_Data!$F$2:$F$801,$C$4,Consolidated_Data!$E$2:$E$801,$C$5,Consolidated_Data!$A$2:$A$801,$C$6,Consolidated_Data!$I$2:$I$801,$C$7,Consolidated_Data!$J$2:$J$801,$C$8) -> 524 | M15: =IFERROR(L15/K15,0) -> 0.80864198 | N15: =COUNTIFS(Consolidated_Data!$C$2:$C$801,"<>",Consolidated_Data!$A$2:$A$801,$J15,Consolidated_Data!$F$2:$F$801,$C$4,Consolidated_Data!$E$2:$E$801,$C$5,Consolidated_Data!$A$2:$A$801,$C$6,Consolidated_Data!$I$2:$I$801,$C$7,Consolidated_Data!$J$2:$J$801,$C$8) -> 12
A16: Advocacy | B16: =SUMIFS(Consolidated_Data!$K$2:$K$801,Consolidated_Data!$C$2:$C$801,"<>",Consolidated_Data!$E$2:$E$801,$A16,Consolidated_Data!$F$2:$F$801,$C$4,Consolidated_Data!$E$2:$E$801,$C$5,Consolidated_Data!$A$2:$A$801,$C$6,Consolidated_Data!$I$2:$I$801,$C$7,Consolidated_Data!$J$2:$J$801,$C$8) -> 576 | C16: =SUMIFS(Consolidated_Data!$L$2:$L$801,Consolidated_Data!$C$2:$C$801,"<>",Consolidated_Data!$E$2:$E$801,$A16,Consolidated_Data!$F$2:$F$801,$C$4,Consolidated_Data!$E$2:$E$801,$C$5,Consolidated_Data!$A$2:$A$801,$C$6,Consolidated_Data!$I$2:$I$801,$C$7,Consolidated_Data!$J$2:$J$801,$C$8) -> 497 | D16: =IFERROR(C16/B16,0) -> 0.86284722 | E16: =COUNTIFS(Consolidated_Data!$C$2:$C$801,"<>",Consolidated_Data!$E$2:$E$801,$A16,Consolidated_Data!$F$2:$F$801,$C$4,Consolidated_Data!$E$2:$E$801,$C$5,Consolidated_Data!$A$2:$A$801,$C$6,Consolidated_Data!$I$2:$I$801,$C$7,Consolidated_Data!$J$2:$J$801,$C$8) -> 12 | G16: Delayed | H16: =COUNTIFS(Consolidated_Data!$C$2:$C$801,"<>",Consolidated_Data!$P$2:$P$801,$G16,Consolidated_Data!$F$2:$F$801,$C$4,Consolidated_Data!$E$2:$E$801,$C$5,Consolidated_Data!$A$2:$A$801,$C$6,Consolidated_Data!$I$2:$I$801,$C$7,Consolidated_Data!$J$2:$J$801,$C$8) -> 0 | J16: OI-104 | K16: =SUMIFS(Consolidated_Data!$K$2:$K$801,Consolidated_Data!$C$2:$C$801,"<>",Consolidated_Data!$A$2:$A$801,$J16,Consolidated_Data!$F$2:$F$801,$C$4,Consolidated_Data!$E$2:$E$801,$C$5,Consolidated_Data!$A$2:$A$801,$C$6,Consolidated_Data!$I$2:$I$801,$C$7,Consolidated_Data!$J$2:$J$801,$C$8) -> 576 | L16: =SUMIFS(Consolidated_Data!$L$2:$L$801,Consolidated_Data!$C$2:$C$801,"<>",Consolidated_Data!$A$2:$A$801,$J16,Consolidated_Data!$F$2:$F$801,$C$4,Consolidated_Data!$E$2:$E$801,$C$5,Consolidated_Data!$A$2:$A$801,$C$6,Consolidated_Data!$I$2:$I$801,$C$7,Consolidated_Data!$J$2:$J$801,$C$8) -> 497 | M16: =IFERROR(L16/K16,0) -> 0.86284722 | N16: =COUNTIFS(Consolidated_Data!$C$2:$C$801,"<>",Consolidated_Data!$A$2:$A$801,$J16,Consolidated_Data!$F$2:$F$801,$C$4,Consolidated_Data!$E$2:$E$801,$C$5,Consolidated_Data!$A$2:$A$801,$C$6,Consolidated_Data!$I$2:$I$801,$C$7,Consolidated_Data!$J$2:$J$801,$C$8) -> 12
G17: Cancelled | H17: =COUNTIFS(Consolidated_Data!$C$2:$C$801,"<>",Consolidated_Data!$P$2:$P$801,$G17,Consolidated_Data!$F$2:$F$801,$C$4,Consolidated_Data!$E$2:$E$801,$C$5,Consolidated_Data!$A$2:$A$801,$C$6,Consolidated_Data!$I$2:$I$801,$C$7,Consolidated_Data!$J$2:$J$801,$C$8) -> 0
A19: By Program Quarter | G19: By Country
A20: Quarter | B20: Planned | C20: Actual | D20: Activities | G20: Country | H20: Planned | I20: Actual | J20: Activities
A21: Y1Q1 | B21: =SUMIFS(Consolidated_Data!$K$2:$K$801,Consolidated_Data!$C$2:$C$801,"<>",Consolidated_Data!$J$2:$J$801,$A21,Consolidated_Data!$F$2:$F$801,$C$4,Consolidated_Data!$E$2:$E$801,$C$5,Consolidated_Data!$A$2:$A$801,$C$6,Consolidated_Data!$I$2:$I$801,$C$7,Consolidated_Data!$J$2:$J$801,$C$8) -> 202 | C21: =SUMIFS(Consolidated_Data!$L$2:$L$801,Consolidated_Data!$C$2:$C$801,"<>",Consolidated_Data!$J$2:$J$801,$A21,Consolidated_Data!$F$2:$F$801,$C$4,Consolidated_Data!$E$2:$E$801,$C$5,Consolidated_Data!$A$2:$A$801,$C$6,Consolidated_Data!$I$2:$I$801,$C$7,Consolidated_Data!$J$2:$J$801,$C$8) -> 215 | D21: =COUNTIFS(Consolidated_Data!$C$2:$C$801,"<>",Consolidated_Data!$J$2:$J$801,$A21,Consolidated_Data!$F$2:$F$801,$C$4,Consolidated_Data!$E$2:$E$801,$C$5,Consolidated_Data!$A$2:$A$801,$C$6,Consolidated_Data!$I$2:$I$801,$C$7,Consolidated_Data!$J$2:$J$801,$C$8) -> 4 | G21: Country_1 | H21: =SUMIFS(Consolidated_Data!$K$2:$K$801,Consolidated_Data!$C$2:$C$801,"<>",Consolidated_Data!$F$2:$F$801,$G21,Consolidated_Data!$F$2:$F$801,$C$4,Consolidated_Data!$E$2:$E$801,$C$5,Consolidated_Data!$A$2:$A$801,$C$6,Consolidated_Data!$I$2:$I$801,$C$7,Consolidated_Data!$J$2:$J$801,$C$8) -> 327 | I21: =SUMIFS(Consolidated_Data!$L$2:$L$801,Consolidated_Data!$C$2:$C$801,"<>",Consolidated_Data!$F$2:$F$801,$G21,Consolidated_Data!$F$2:$F$801,$C$4,Consolidated_Data!$E$2:$E$801,$C$5,Consolidated_Data!$A$2:$A$801,$C$6,Consolidated_Data!$I$2:$I$801,$C$7,Consolidated_Data!$J$2:$J$801,$C$8) -> 327 | J21: =COUNTIFS(Consolidated_Data!$C$2:$C$801,"<>",Consolidated_Data!$F$2:$F$801,$G21,Consolidated_Data!$F$2:$F$801,$C$4,Consolidated_Data!$E$2:$E$801,$C$5,Consolidated_Data!$A$2:$A$801,$C$6,Consolidated_Data!$I$2:$I$801,$C$7,Consolidated_Data!$J$2:$J$801,$C$8) -> 6
A22: Y1Q2 | B22: =SUMIFS(Consolidated_Data!$K$2:$K$801,Consolidated_Data!$C$2:$C$801,"<>",Consolidated_Data!$J$2:$J$801,$A22,Consolidated_Data!$F$2:$F$801,$C$4,Consolidated_Data!$E$2:$E$801,$C$5,Consolidated_Data!$A$2:$A$801,$C$6,Consolidated_Data!$I$2:$I$801,$C$7,Consolidated_Data!$J$2:$J$801,$C$8) -> 222 | C22: =SUMIFS(Consolidated_Data!$L$2:$L$801,Consolidated_Data!$C$2:$C$801,"<>",Consolidated_Data!$J$2:$J$801,$A22,Consolidated_Data!$F$2:$F$801,$C$4,Consolidated_Data!$E$2:$E$801,$C$5,Consolidated_Data!$A$2:$A$801,$C$6,Consolidated_Data!$I$2:$I$801,$C$7,Consolidated_Data!$J$2:$J$801,$C$8) -> 219 | D22: =COUNTIFS(Consolidated_Data!$C$2:$C$801,"<>",Consolidated_Data!$J$2:$J$801,$A22,Consolidated_Data!$F$2:$F$801,$C$4,Consolidated_Data!$E$2:$E$801,$C$5,Consolidated_Data!$A$2:$A$801,$C$6,Consolidated_Data!$I$2:$I$801,$C$7,Consolidated_Data!$J$2:$J$801,$C$8) -> 4 | G22: Country_2 | H22: =SUMIFS(Consolidated_Data!$K$2:$K$801,Consolidated_Data!$C$2:$C$801,"<>",Consolidated_Data!$F$2:$F$801,$G22,Consolidated_Data!$F$2:$F$801,$C$4,Consolidated_Data!$E$2:$E$801,$C$5,Consolidated_Data!$A$2:$A$801,$C$6,Consolidated_Data!$I$2:$I$801,$C$7,Consolidated_Data!$J$2:$J$801,$C$8) -> 369 | I22: =SUMIFS(Consolidated_Data!$L$2:$L$801,Consolidated_Data!$C$2:$C$801,"<>",Consolidated_Data!$F$2:$F$801,$G22,Consolidated_Data!$F$2:$F$801,$C$4,Consolidated_Data!$E$2:$E$801,$C$5,Consolidated_Data!$A$2:$A$801,$C$6,Consolidated_Data!$I$2:$I$801,$C$7,Consolidated_Data!$J$2:$J$801,$C$8) -> 233 | J22: =COUNTIFS(Consolidated_Data!$C$2:$C$801,"<>",Consolidated_Data!$F$2:$F$801,$G22,Consolidated_Data!$F$2:$F$801,$C$4,Consolidated_Data!$E$2:$E$801,$C$5,Consolidated_Data!$A$2:$A$801,$C$6,Consolidated_Data!$I$2:$I$801,$C$7,Consolidated_Data!$J$2:$J$801,$C$8) -> 6
A23: Y1Q3 | B23: =SUMIFS(Consolidated_Data!$K$2:$K$801,Consolidated_Data!$C$2:$C$801,"<>",Consolidated_Data!$J$2:$J$801,$A23,Consolidated_Data!$F$2:$F$801,$C$4,Consolidated_Data!$E$2:$E$801,$C$5,Consolidated_Data!$A$2:$A$801,$C$6,Consolidated_Data!$I$2:$I$801,$C$7,Consolidated_Data!$J$2:$J$801,$C$8) -> 192 | C23: =SUMIFS(Consolidated_Data!$L$2:$L$801,Consolidated_Data!$C$2:$C$801,"<>",Consolidated_Data!$J$2:$J$801,$A23,Consolidated_Data!$F$2:$F$801,$C$4,Consolidated_Data!$E$2:$E$801,$C$5,Consolidated_Data!$A$2:$A$801,$C$6,Consolidated_Data!$I$2:$I$801,$C$7,Consolidated_Data!$J$2:$J$801,$C$8) -> 194 | D23: =COUNTIFS(Consolidated_Data!$C$2:$C$801,"<>",Consolidated_Data!$J$2:$J$801,$A23,Consolidated_Data!$F$2:$F$801,$C$4,Consolidated_Data!$E$2:$E$801,$C$5,Consolidated_Data!$A$2:$A$801,$C$6,Consolidated_Data!$I$2:$I$801,$C$7,Consolidated_Data!$J$2:$J$801,$C$8) -> 4 | G23: Country_3 | H23: =SUMIFS(Consolidated_Data!$K$2:$K$801,Consolidated_Data!$C$2:$C$801,"<>",Consolidated_Data!$F$2:$F$801,$G23,Consolidated_Data!$F$2:$F$801,$C$4,Consolidated_Data!$E$2:$E$801,$C$5,Consolidated_Data!$A$2:$A$801,$C$6,Consolidated_Data!$I$2:$I$801,$C$7,Consolidated_Data!$J$2:$J$801,$C$8) -> 361 | I23: =SUMIFS(Consolidated_Data!$L$2:$L$801,Consolidated_Data!$C$2:$C$801,"<>",Consolidated_Data!$F$2:$F$801,$G23,Consolidated_Data!$F$2:$F$801,$C$4,Consolidated_Data!$E$2:$E$801,$C$5,Consolidated_Data!$A$2:$A$801,$C$6,Consolidated_Data!$I$2:$I$801,$C$7,Consolidated_Data!$J$2:$J$801,$C$8) -> 355 | J23: =COUNTIFS(Consolidated_Data!$C$2:$C$801,"<>",Consolidated_Data!$F$2:$F$801,$G23,Consolidated_Data!$F$2:$F$801,$C$4,Consolidated_Data!$E$2:$E$801,$C$5,Consolidated_Data!$A$2:$A$801,$C$6,Consolidated_Data!$I$2:$I$801,$C$7,Consolidated_Data!$J$2:$J$801,$C$8) -> 6
A24: Y1Q4 | B24: =SUMIFS(Consolidated_Data!$K$2:$K$801,Consolidated_Data!$C$2:$C$801,"<>",Consolidated_Data!$J$2:$J$801,$A24,Consolidated_Data!$F$2:$F$801,$C$4,Consolidated_Data!$E$2:$E$801,$C$5,Consolidated_Data!$A$2:$A$801,$C$6,Consolidated_Data!$I$2:$I$801,$C$7,Consolidated_Data!$J$2:$J$801,$C$8) -> 212 | C24: =SUMIFS(Consolidated_Data!$L$2:$L$801,Consolidated_Data!$C$2:$C$801,"<>",Consolidated_Data!$J$2:$J$801,$A24,Consolidated_Data!$F$2:$F$801,$C$4,Consolidated_Data!$E$2:$E$801,$C$5,Consolidated_Data!$A$2:$A$801,$C$6,Consolidated_Data!$I$2:$I$801,$C$7,Consolidated_Data!$J$2:$J$801,$C$8) -> 219 | D24: =COUNTIFS(Consolidated_Data!$C$2:$C$801,"<>",Consolidated_Data!$J$2:$J$801,$A24,Consolidated_Data!$F$2:$F$801,$C$4,Consolidated_Data!$E$2:$E$801,$C$5,Consolidated_Data!$A$2:$A$801,$C$6,Consolidated_Data!$I$2:$I$801,$C$7,Consolidated_Data!$J$2:$J$801,$C$8) -> 4 | G24: Country_4 | H24: =SUMIFS(Consolidated_Data!$K$2:$K$801,Consolidated_Data!$C$2:$C$801,"<>",Consolidated_Data!$F$2:$F$801,$G24,Consolidated_Data!$F$2:$F$801,$C$4,Consolidated_Data!$E$2:$E$801,$C$5,Consolidated_Data!$A$2:$A$801,$C$6,Consolidated_Data!$I$2:$I$801,$C$7,Consolidated_Data!$J$2:$J$801,$C$8) -> 353 | I24: =SUMIFS(Consolidated_Data!$L$2:$L$801,Consolidated_Data!$C$2:$C$801,"<>",Consolidated_Data!$F$2:$F$801,$G24,Consolidated_Data!$F$2:$F$801,$C$4,Consolidated_Data!$E$2:$E$801,$C$5,Consolidated_Data!$A$2:$A$801,$C$6,Consolidated_Data!$I$2:$I$801,$C$7,Consolidated_Data!$J$2:$J$801,$C$8) -> 271 | J24: =COUNTIFS(Consolidated_Data!$C$2:$C$801,"<>",Consolidated_Data!$F$2:$F$801,$G24,Consolidated_Data!$F$2:$F$801,$C$4,Consolidated_Data!$E$2:$E$801,$C$5,Consolidated_Data!$A$2:$A$801,$C$6,Consolidated_Data!$I$2:$I$801,$C$7,Consolidated_Data!$J$2:$J$801,$C$8) -> 6
A25: Y2Q1 | B25: =SUMIFS(Consolidated_Data!$K$2:$K$801,Consolidated_Data!$C$2:$C$801,"<>",Consolidated_Data!$J$2:$J$801,$A25,Consolidated_Data!$F$2:$F$801,$C$4,Consolidated_Data!$E$2:$E$801,$C$5,Consolidated_Data!$A$2:$A$801,$C$6,Consolidated_Data!$I$2:$I$801,$C$7,Consolidated_Data!$J$2:$J$801,$C$8) -> 232 | C25: =SUMIFS(Consolidated_Data!$L$2:$L$801,Consolidated_Data!$C$2:$C$801,"<>",Consolidated_Data!$J$2:$J$801,$A25,Consolidated_Data!$F$2:$F$801,$C$4,Consolidated_Data!$E$2:$E$801,$C$5,Consolidated_Data!$A$2:$A$801,$C$6,Consolidated_Data!$I$2:$I$801,$C$7,Consolidated_Data!$J$2:$J$801,$C$8) -> 223 | D25: =COUNTIFS(Consolidated_Data!$C$2:$C$801,"<>",Consolidated_Data!$J$2:$J$801,$A25,Consolidated_Data!$F$2:$F$801,$C$4,Consolidated_Data!$E$2:$E$801,$C$5,Consolidated_Data!$A$2:$A$801,$C$6,Consolidated_Data!$I$2:$I$801,$C$7,Consolidated_Data!$J$2:$J$801,$C$8) -> 4 | G25: Country_5 | H25: =SUMIFS(Consolidated_Data!$K$2:$K$801,Consolidated_Data!$C$2:$C$801,"<>",Consolidated_Data!$F$2:$F$801,$G25,Consolidated_Data!$F$2:$F$801,$C$4,Consolidated_Data!$E$2:$E$801,$C$5,Consolidated_Data!$A$2:$A$801,$C$6,Consolidated_Data!$I$2:$I$801,$C$7,Consolidated_Data!$J$2:$J$801,$C$8) -> 295 | I25: =SUMIFS(Consolidated_Data!$L$2:$L$801,Consolidated_Data!$C$2:$C$801,"<>",Consolidated_Data!$F$2:$F$801,$G25,Consolidated_Data!$F$2:$F$801,$C$4,Consolidated_Data!$E$2:$E$801,$C$5,Consolidated_Data!$A$2:$A$801,$C$6,Consolidated_Data!$I$2:$I$801,$C$7,Consolidated_Data!$J$2:$J$801,$C$8) -> 304 | J25: =COUNTIFS(Consolidated_Data!$C$2:$C$801,"<>",Consolidated_Data!$F$2:$F$801,$G25,Consolidated_Data!$F$2:$F$801,$C$4,Consolidated_Data!$E$2:$E$801,$C$5,Consolidated_Data!$A$2:$A$801,$C$6,Consolidated_Data!$I$2:$I$801,$C$7,Consolidated_Data!$J$2:$J$801,$C$8) -> 6
A26: Y2Q2 | B26: =SUMIFS(Consolidated_Data!$K$2:$K$801,Consolidated_Data!$C$2:$C$801,"<>",Consolidated_Data!$J$2:$J$801,$A26,Consolidated_Data!$F$2:$F$801,$C$4,Consolidated_Data!$E$2:$E$801,$C$5,Consolidated_Data!$A$2:$A$801,$C$6,Consolidated_Data!$I$2:$I$801,$C$7,Consolidated_Data!$J$2:$J$801,$C$8) -> 202 | C26: =SUMIFS(Consolidated_Data!$L$2:$L$801,Consolidated_Data!$C$2:$C$801,"<>",Consolidated_Data!$J$2:$J$801,$A26,Consolidated_Data!$F$2:$F$801,$C$4,Consolidated_Data!$E$2:$E$801,$C$5,Consolidated_Data!$A$2:$A$801,$C$6,Consolidated_Data!$I$2:$I$801,$C$7,Consolidated_Data!$J$2:$J$801,$C$8) -> 198 | D26: =COUNTIFS(Consolidated_Data!$C$2:$C$801,"<>",Consolidated_Data!$J$2:$J$801,$A26,Consolidated_Data!$F$2:$F$801,$C$4,Consolidated_Data!$E$2:$E$801,$C$5,Consolidated_Data!$A$2:$A$801,$C$6,Consolidated_Data!$I$2:$I$801,$C$7,Consolidated_Data!$J$2:$J$801,$C$8) -> 4 | G26: Country_6 | H26: =SUMIFS(Consolidated_Data!$K$2:$K$801,Consolidated_Data!$C$2:$C$801,"<>",Consolidated_Data!$F$2:$F$801,$G26,Consolidated_Data!$F$2:$F$801,$C$4,Consolidated_Data!$E$2:$E$801,$C$5,Consolidated_Data!$A$2:$A$801,$C$6,Consolidated_Data!$I$2:$I$801,$C$7,Consolidated_Data!$J$2:$J$801,$C$8) -> 287 | I26: =SUMIFS(Consolidated_Data!$L$2:$L$801,Consolidated_Data!$C$2:$C$801,"<>",Consolidated_Data!$F$2:$F$801,$G26,Consolidated_Data!$F$2:$F$801,$C$4,Consolidated_Data!$E$2:$E$801,$C$5,Consolidated_Data!$A$2:$A$801,$C$6,Consolidated_Data!$I$2:$I$801,$C$7,Consolidated_Data!$J$2:$J$801,$C$8) -> 180 | J26: =COUNTIFS(Consolidated_Data!$C$2:$C$801,"<>",Consolidated_Data!$F$2:$F$801,$G26,Consolidated_Data!$F$2:$F$801,$C$4,Consolidated_Data!$E$2:$E$801,$C$5,Consolidated_Data!$A$2:$A$801,$C$6,Consolidated_Data!$I$2:$I$801,$C$7,Consolidated_Data!$J$2:$J$801,$C$8) -> 6
A27: Y2Q3 | B27: =SUMIFS(Consolidated_Data!$K$2:$K$801,Consolidated_Data!$C$2:$C$801,"<>",Consolidated_Data!$J$2:$J$801,$A27,Consolidated_Data!$F$2:$F$801,$C$4,Consolidated_Data!$E$2:$E$801,$C$5,Consolidated_Data!$A$2:$A$801,$C$6,Consolidated_Data!$I$2:$I$801,$C$7,Consolidated_Data!$J$2:$J$801,$C$8) -> 230 | C27: =SUMIFS(Consolidated_Data!$L$2:$L$801,Consolidated_Data!$C$2:$C$801,"<>",Consolidated_Data!$J$2:$J$801,$A27,Consolidated_Data!$F$2:$F$801,$C$4,Consolidated_Data!$E$2:$E$801,$C$5,Consolidated_Data!$A$2:$A$801,$C$6,Consolidated_Data!$I$2:$I$801,$C$7,Consolidated_Data!$J$2:$J$801,$C$8) -> 234 | D27: =COUNTIFS(Consolidated_Data!$C$2:$C$801,"<>",Consolidated_Data!$J$2:$J$801,$A27,Consolidated_Data!$F$2:$F$801,$C$4,Consolidated_Data!$E$2:$E$801,$C$5,Consolidated_Data!$A$2:$A$801,$C$6,Consolidated_Data!$I$2:$I$801,$C$7,Consolidated_Data!$J$2:$J$801,$C$8) -> 4 | G27: Country_7 | H27: =SUMIFS(Consolidated_Data!$K$2:$K$801,Consolidated_Data!$C$2:$C$801,"<>",Consolidated_Data!$F$2:$F$801,$G27,Consolidated_Data!$F$2:$F$801,$C$4,Consolidated_Data!$E$2:$E$801,$C$5,Consolidated_Data!$A$2:$A$801,$C$6,Consolidated_Data!$I$2:$I$801,$C$7,Consolidated_Data!$J$2:$J$801,$C$8) -> 279 | I27: =SUMIFS(Consolidated_Data!$L$2:$L$801,Consolidated_Data!$C$2:$C$801,"<>",Consolidated_Data!$F$2:$F$801,$G27,Consolidated_Data!$F$2:$F$801,$C$4,Consolidated_Data!$E$2:$E$801,$C$5,Consolidated_Data!$A$2:$A$801,$C$6,Consolidated_Data!$I$2:$I$801,$C$7,Consolidated_Data!$J$2:$J$801,$C$8) -> 282 | J27: =COUNTIFS(Consolidated_Data!$C$2:$C$801,"<>",Consolidated_Data!$F$2:$F$801,$G27,Consolidated_Data!$F$2:$F$801,$C$4,Consolidated_Data!$E$2:$E$801,$C$5,Consolidated_Data!$A$2:$A$801,$C$6,Consolidated_Data!$I$2:$I$801,$C$7,Consolidated_Data!$J$2:$J$801,$C$8) -> 6
A28: Y2Q4 | B28: =SUMIFS(Consolidated_Data!$K$2:$K$801,Consolidated_Data!$C$2:$C$801,"<>",Consolidated_Data!$J$2:$J$801,$A28,Consolidated_Data!$F$2:$F$801,$C$4,Consolidated_Data!$E$2:$E$801,$C$5,Consolidated_Data!$A$2:$A$801,$C$6,Consolidated_Data!$I$2:$I$801,$C$7,Consolidated_Data!$J$2:$J$801,$C$8) -> 200 | C28: =SUMIFS(Consolidated_Data!$L$2:$L$801,Consolidated_Data!$C$2:$C$801,"<>",Consolidated_Data!$J$2:$J$801,$A28,Consolidated_Data!$F$2:$F$801,$C$4,Consolidated_Data!$E$2:$E$801,$C$5,Consolidated_Data!$A$2:$A$801,$C$6,Consolidated_Data!$I$2:$I$801,$C$7,Consolidated_Data!$J$2:$J$801,$C$8) -> 209 | D28: =COUNTIFS(Consolidated_Data!$C$2:$C$801,"<>",Consolidated_Data!$J$2:$J$801,$A28,Consolidated_Data!$F$2:$F$801,$C$4,Consolidated_Data!$E$2:$E$801,$C$5,Consolidated_Data!$A$2:$A$801,$C$6,Consolidated_Data!$I$2:$I$801,$C$7,Consolidated_Data!$J$2:$J$801,$C$8) -> 4 | G28: Country_8 | H28: =SUMIFS(Consolidated_Data!$K$2:$K$801,Consolidated_Data!$C$2:$C$801,"<>",Consolidated_Data!$F$2:$F$801,$G28,Consolidated_Data!$F$2:$F$801,$C$4,Consolidated_Data!$E$2:$E$801,$C$5,Consolidated_Data!$A$2:$A$801,$C$6,Consolidated_Data!$I$2:$I$801,$C$7,Consolidated_Data!$J$2:$J$801,$C$8) -> 321 | I28: =SUMIFS(Consolidated_Data!$L$2:$L$801,Consolidated_Data!$C$2:$C$801,"<>",Consolidated_Data!$F$2:$F$801,$G28,Consolidated_Data!$F$2:$F$801,$C$4,Consolidated_Data!$E$2:$E$801,$C$5,Consolidated_Data!$A$2:$A$801,$C$6,Consolidated_Data!$I$2:$I$801,$C$7,Consolidated_Data!$J$2:$J$801,$C$8) -> 210 | J28: =COUNTIFS(Consolidated_Data!$C$2:$C$801,"<>",Consolidated_Data!$F$2:$F$801,$G28,Consolidated_Data!$F$2:$F$801,$C$4,Consolidated_Data!$E$2:$E$801,$C$5,Consolidated_Data!$A$2:$A$801,$C$6,Consolidated_Data!$I$2:$I$801,$C$7,Consolidated_Data!$J$2:$J$801,$C$8) -> 6
A29: Y3Q1 | B29: =SUMIFS(Consolidated_Data!$K$2:$K$801,Consolidated_Data!$C$2:$C$801,"<>",Consolidated_Data!$J$2:$J$801,$A29,Consolidated_Data!$F$2:$F$801,$C$4,Consolidated_Data!$E$2:$E$801,$C$5,Consolidated_Data!$A$2:$A$801,$C$6,Consolidated_Data!$I$2:$I$801,$C$7,Consolidated_Data!$J$2:$J$801,$C$8) -> 220 | C29: =SUMIFS(Consolidated_Data!$L$2:$L$801,Consolidated_Data!$C$2:$C$801,"<>",Consolidated_Data!$J$2:$J$801,$A29,Consolidated_Data!$F$2:$F$801,$C$4,Consolidated_Data!$E$2:$E$801,$C$5,Consolidated_Data!$A$2:$A$801,$C$6,Consolidated_Data!$I$2:$I$801,$C$7,Consolidated_Data!$J$2:$J$801,$C$8) -> 213 | D29: =COUNTIFS(Consolidated_Data!$C$2:$C$801,"<>",Consolidated_Data!$J$2:$J$801,$A29,Consolidated_Data!$F$2:$F$801,$C$4,Consolidated_Data!$E$2:$E$801,$C$5,Consolidated_Data!$A$2:$A$801,$C$6,Consolidated_Data!$I$2:$I$801,$C$7,Consolidated_Data!$J$2:$J$801,$C$8) -> 4
A30: Y3Q2 | B30: =SUMIFS(Consolidated_Data!$K$2:$K$801,Consolidated_Data!$C$2:$C$801,"<>",Consolidated_Data!$J$2:$J$801,$A30,Consolidated_Data!$F$2:$F$801,$C$4,Consolidated_Data!$E$2:$E$801,$C$5,Consolidated_Data!$A$2:$A$801,$C$6,Consolidated_Data!$I$2:$I$801,$C$7,Consolidated_Data!$J$2:$J$801,$C$8) -> 240 | C30: =SUMIFS(Consolidated_Data!$L$2:$L$801,Consolidated_Data!$C$2:$C$801,"<>",Consolidated_Data!$J$2:$J$801,$A30,Consolidated_Data!$F$2:$F$801,$C$4,Consolidated_Data!$E$2:$E$801,$C$5,Consolidated_Data!$A$2:$A$801,$C$6,Consolidated_Data!$I$2:$I$801,$C$7,Consolidated_Data!$J$2:$J$801,$C$8) -> 238 | D30: =COUNTIFS(Consolidated_Data!$C$2:$C$801,"<>",Consolidated_Data!$J$2:$J$801,$A30,Consolidated_Data!$F$2:$F$801,$C$4,Consolidated_Data!$E$2:$E$801,$C$5,Consolidated_Data!$A$2:$A$801,$C$6,Consolidated_Data!$I$2:$I$801,$C$7,Consolidated_Data!$J$2:$J$801,$C$8) -> 4
